2025-03-10 15:54:33,808 - kmip.server - DEBUG - DH-RSA-AES256-SHA256
2025-03-10 15:54:33,817 - kmip.server - DEBUG - DHE-DSS-AES256-SHA256
2025-03-10 15:54:33,817 - kmip.server - DEBUG - DHE-RSA-AES256-SHA256
2025-03-10 15:54:33,817 - kmip.server - DEBUG - ECDH-ECDSA-AES128-SHA256
2025-03-10 15:54:33,818 - kmip.server - DEBUG - ECDH-ECDSA-AES256-SHA256
2025-03-10 15:54:33,818 - kmip.server - DEBUG - ECDHE-ECDSA-AES128-SHA256
2025-03-10 15:54:33,819 - kmip.server - DEBUG - ECDHE-ECDSA-AES256-SHA384
2025-03-10 15:54:33,819 - kmip.server - DEBUG - ECDH-RSA-AES128-SHA256
2025-03-10 15:54:33,824 - kmip.server - DEBUG - ECDH-RSA-AES256-SHA384
2025-03-10 15:54:33,824 - kmip.server - DEBUG - ECDHE-RSA-AES128-SHA256
2025-03-10 15:54:33,824 - kmip.server - DEBUG - ECDHE-RSA-AES256-SHA384
2025-03-10 15:54:33,825 - kmip.server - DEBUG - ECDHE-ECDSA-AES128-GCM-SHA256
2025-03-10 15:54:33,825 - kmip.server - DEBUG - ECDHE-ECDSA-AES256-GCM-SHA384
2025-03-10 15:54:33,825 - kmip.server - DEBUG - ECDHE-ECDSA-AES128-SHA256
2025-03-10 15:54:33,826 - kmip.server - DEBUG - ECDHE-ECDSA-AES256-SHA384
2025-03-10 15:54:33,832 - kmip.server - ERROR - [Errno 98] Address already in use
Traceback (most recent call last):
  File "kmip/services/server/server.py", line 304, in start
OSError: [Errno 98] Address already in use
